Workbook

Sheet ReadMe
A1: TAM / SAM / SOM Model: Trailer Park, the audience-demand layer for unproduced stories
A2: Granular bottoms-up build. Prepared 19 September 2026. Layout follows the team's granular model convention. All figures USD per year.
A4: METHOD
A5: TAM is defined as CURRENT SPEND on the problem, on both sides of the market. B2B: what studios, streamers, producers, financiers and sales agents already pay to decide what to make (audience research, demand analytics, script evaluation) plus what writers and small production companies already pay to get a script noticed, packaged and sold. B2C: what fans already pay to take part in film (a membership with a vote, a pledge, a film identity). The two pools are quoted separately. B2B is the revenue market today. B2C is proof of appetite: today fans never pay to vote, so it becomes addressable only if pledges or a membership are adopted (open decision). The build excludes the money being decided ($255B of content spend, $33.6B of box office), internal story departments, our own planned success fee, creator memberships, cinema subscriptions, advertising attention, the short-drama app market, and the expansion effect of AI lowering the cost of a test from $10-25K to under $200; the excluded lines are kept as MEMO rows so a reader can see them. Value at stake is shown on the summary as context and is never added to TAM.
A7: HOW TO USE
A8: Every input is a blue cell on the Assumptions tab with Low / Base / High columns. The Low column always holds the TAM-minimising end. The TAM Build tab pulls each variable over from Assumptions (green cells) so every line shows its own arithmetic, with the calculated line directly beneath its drivers and a summary table at the bottom. Market size is presented in layers that must never be conflated in external documents: TAM (global current spend); SAM-NOW (the same spend inside the V1 wedge: English-language, US + UK, horror and genre first); REACHABLE REVENUE (wedge organisations at planned list prices); and SOM (the year-5 revenue plan). Check rows compare the layers. Rows marked MEMO are shown for context and are not summed. Yellow cells are the highest-leverage assumptions. Every computed cell is a live formula.
A10: COLOUR LEGEND
A11: Blue text = input (Assumptions tab). Green text = variable pulled from another tab. Black text = calculation. Yellow fill = key lever. Grey italic = source or note. Shaded rows = subtotals and results. Source tags: SOURCED = published figure; DERIVED = arithmetic on sourced figures; ESTIMATE = analyst judgement, anchor stated; HYPOTHESIS = our own price or plan, untested.
A13: KEY SOURCES
A14: Ampere Analysis (global content spend 2026, $255B). Gower Street Analytics (global box office 2025, $33.6B). Angel Studios Q2 2026 results (2.61M paying Guild members, $90.7M quarterly Guild revenue). Kickstarter and Seed&Spark public stats. Patreon via Axios (Aug 2025). Letterboxd via TIME (2026). Sensor Tower State of Short Drama Apps 2026; Deloitte TMT Predictions 2026. ESOMAR Global Market Research ($153B insights industry, context only). WGA Schedule of Minimums; WGAW annual report via THR. MovieBytes contest logs (Austin, PAGE). Sundance 2026 submissions; Cannes Marche and AFM 2025 facts and figures. Comscore via TheWrap (wide releases). Cinema United 2025 (200M+ moviegoers) and Deadline (780M admissions, 2025). Vendor revenue figures are scraped company-profile estimates and are tagged low reliability.
A16: WHAT THE MODEL SAYS (base case)
A17: 1) The industry decides $255B a year and buys about $0.36B of help deciding (research, analytics, script coverage), roughly 0.14%. About $0.15B of that asks an audience, and only ~$13M asks before a film exists, because today's test costs $10-25K and needs a finished film. 2) Writers and small producers spend another ~$0.08B getting scripts seen: B2B TAM ~$0.45B. 3) Fans already pay about the same again, ~$0.45B a year, to take part in film, and the closest comparable (a guild membership that includes a vote on releases) grew 99% in twelve months. 4) The business case is category expansion, not share-taking: at list prices the wedge's reachable revenue is about equal to everything those buyers spend today, and the $48K seat is about twice their data-tool budget.
... A20: 1) Paying guild members, and what share of that fee really buys the vote. 2) Tier 1 analytics spend per buyer and buyer count: no public contract data. 3) Research vendor revenue, the other-vendor multiplier and the pre-greenlight share. 4) Packaging spend per project and the count of projects packaged. 5) Reachable wedge organisations: the count is an estimate until the Enumeration tab is filled; horror affinity and the share of fans who pay drive the B2C SAM. 6) Monthly actives as a share of registered fans: a 25-trailer horror feed test answers it cheaply. OPEN RECONCILIATION: the bottom-up year-5 plan implies capturing ~15% of B2B SAM-now, above the 3-10% top-down band. The gap is the category-expansion bet (testing scripts nobody tests today); paid pilots must close it from the evidence side or the SOM comes down. OPEN DECISION: B2C monetisation. Under the current stance (no ads, no pay-to-vote) B2C is the engine that produces the signal and the owned audience, not a revenue line.

Sheet Assumptions
A1: Assumptions (blue = input; Low column = TAM-minimising end of each input; USD per year)
A3: Input | B3: Low | C3: Base | D3: High | E3: Source / note
A4: B2B BUYER SIDE · SEGMENT A: AUDIENCE AND CONCEPT RESEARCH (studios, streamers)
A5: Largest entertainment research vendor, revenue ($/yr) | B5: 94000000 | C5: 94000000 | D5: 94000000 | E5: SOURCED, low reliability: scraped company-profile estimate for National Research Group (growjo.com). Validate against the Stagwell 10-K segment note. Held constant.
A6: Share of that revenue that is film and TV (%) | B6: 0.5 | C6: 0.65 | D6: 1 | E6: ESTIMATE. Vendor has diversified into tech, gaming and sports.
A7: Second vendor, revenue ($/yr) | B7: 43700000 | C7: 43700000 | D7: 43700000 | E7: SOURCED, low reliability: Screen Engine/ASI estimate (datanyze.com). Held constant.
A8: Share of that revenue that is film and TV (%) | B8: 0.8 | C8: 0.9 | D8: 1 | E8: ESTIMATE.
A9: Multiplier for all other vendors (x) | B9: 1 | C9: 1.5 | D9: 2 | E9: ESTIMATE. Covers tracking, exit polling, concept and trailer testing suppliers. Cross-check: ~105 wide releases x ~$750K research per title = $79M before streamers and TV.
A10: MEMO North American wide releases (count/yr) | B10: 95 | C10: 105 | D10: 115 | E10: SOURCED: Comscore via TheWrap, 101 (2023), ~110 (2025E).
A11: MEMO Share of wide releases test-screened (%) | B11: 0.75 | C11: 0.85 | D11: 0.9 | E11: SOURCED, weak: "90% of wide studio films, average three screenings" (Goetz / BBC 2022 via Wikipedia, Test screening).
A12: MEMO Screenings per tested wide title (count) | B12: 2 | C12: 3 | D12: 4 | E12: Same source.
A13: MEMO Cost per recruited studio screening ($) | B13: 10000 | C13: 15000 | D13: 25000 | E13: SOURCED: $10-20K for 300-500 seats (dawsonagents.com guide). The $25K figure on scene 2 of the deck (Forbes 2017) is carried as the High only.
A14: MEMO Other screenings: limited, streamer films, series (US, $/yr) | B14: 1710000 | C14: 9200000 | D14: 33000000 | E14: ESTIMATE built from release and series counts (The Numbers; Netflix originals count; FX tally of 516 scripted series 2023) x share tested x screenings x cost.
A15: MEMO Rest-of-world uplift on screenings (x) | B15: 1.15 | C15: 1.3 | D15: 1.5 | E15: ESTIMATE. Test screening is mainly a US/UK practice.
A16: MEMO Pre-greenlight share of non-screening research (%) | B16: 0.05 | C16: 0.1 | D16: 0.15 | E16: ESTIMATE. Most research money is spent after the film exists. This is the slice a Demand Certificate directly replaces.
A17: B2B BUYER SIDE · SEGMENT B: DEMAND ANALYTICS AND DATA SUBSCRIPTIONS
A18: Tier 1 buyers: majors, global streamers, large broadcaster groups (count) | B18: 25 | C18: 40 | D18: 60 | E18: ESTIMATE.
A19: Tier 1 content-analytics spend per buyer ($/yr) | B19: 1000000 | C19: 2500000 | D19: 5000000 | E19: ESTIMATE. No public contract values. Excludes ratings currency (Nielsen, Comscore TV) and excludes the research vendors already counted in segment A.
A20: Tier 2 buyers: mini-majors, regional streamers, scripted commissioners, top distributors (count) | B20: 150 | C20: 300 | D20: 500 | E20: ESTIMATE.
A21: Tier 2 annual contract value ($/yr) | B21: 100000 | C21: 200000 | D21: 350000 | E21: ESTIMATE, in line with the planned $90-150K data-feed price.
A22: Tier 3 buyers: independents, sales agents, financiers (count) | B22: 1000 | C22: 2000 | D22: 4000 | E22: ESTIMATE anchored to SOURCED counts: AFM 2025 285 exhibiting companies; Cannes Marche 600+ exhibitors and ~4,000 films and projects; IFTA 70+ members.
A23: Tier 3 annual tool spend ($/yr) | B23: 3000 | C23: 8000 | D23: 15000 | E23: ESTIMATE. Professional database and box-office data subscriptions.
A24: B2B BUYER SIDE · SEGMENT C: SCRIPT EVALUATION (coverage, readers, story departments)
A25: US companies with a real development function (count) | B25: 800 | C25: 1500 | D25: 3000 | E25: DERIVED: IBISWorld 50,981 US production businesses (2025) x 1.5-6%; BFI found ~7.5% of UK companies made a feature.
A26: Coverage and evaluation spend per company ($/yr) | B26: 10000 | C26: 25000 | D26: 50000 | E26: ESTIMATE.
A27: MEMO Major and streamer story departments (count) | B27: 40 | C27: 40 | D27: 40 | E27: ESTIMATE. Internal salaries, not purchasable spend: shown as a memo only. Held constant.
A28: MEMO Story department cost ($/yr) | B28: 500000 | C28: 1000000 | D28: 2000000 | E28: ESTIMATE.
A29: B2B BUYER SIDE · MEMO D: SCRIPT ACQUISITION (our own planned success fee; not current spend, so not in TAM)
A30: Studio-level spec sales (count/yr) | B30: 40 | C30: 70 | D30: 120 | E30: Anchors SOURCED: 124 (2013), 132 (2011-12) per Scoggins Report; summer 2025 had 23 sales (Final Draft). The 2020s annual count is an ESTIMATE.
A31: Average spec purchase price ($) | B31: 150000 | C31: 300000 | D31: 500000 | E31: ESTIMATE. WGA 2025-26 minimums SOURCED: $90,904 (budget under $5M), $170,655 (over).
A32: Independent US+UK script purchases (count/yr) | B32: 120 | C32: 240 | D32: 480 | E32: ESTIMATE: 600/800/1,200 independent features x 20/30/40% bought from a third-party writer.
A33: Independent purchase price ($) | B33: 20000 | C33: 40000 | D33: 75000 | E33: SOURCED range $15-100K (scriptlix.com, 2026).
A34: Independent options (count/yr) | B34: 360 | C34: 960 | D34: 2400 | E34: ESTIMATE: three to five options per purchase.
A35: Option price ($) | B35: 1000 | C35: 5000 | D35: 10000 | E35: SOURCED range $1-50K, same source.
A36: Success fee on purchases (%) | B36: 0.01 | C36: 0.015 | D36: 0.02 | E36: Planned fee, project instructions: 1-2% of purchase price. Counsel to confirm against the Talent Agencies Act.
A37: Success fee on options (%) | B37: 0.03 | C37: 0.04 | D37: 0.05 | E37: Planned fee, project instructions: 3-5% of option.
A38: B2B CREATOR SIDE · SEGMENT E: WRITERS AND SMALL PRODUCTION COMPANIES (spend to get a script noticed, packaged, sold)
A39: Paid screenplay contest entries, all contests (count/yr) | B39: 120000 | C39: 200000 | D39: 350000 | E39: ESTIMATE. Top ~10 contests total ~60K (SOURCED: Austin 11.5-14.6K, PAGE 9.1-10.5K via MovieBytes); 449 contests listed on MovieBytes. Count spend, not people: ~50K paying writers enter ~4 each.
A40: Average entry fee ($) | B40: 45 | C40: 60 | D40: 75 | E40: DERIVED from published fee tables: Austin $50-90, PAGE $49+, Big Break $45-155.
A41: Entries buying the feedback add-on (%) | B41: 0.1 | C41: 0.15 | D41: 0.2 | E41: ESTIMATE.
...

Sheet TAM Build
A1: TAM Build: variables pulled from Assumptions (green), calculations beneath them (black), summary at bottom
A3: Line | B3: Low | C3: Base | D3: High | E3: Build logic
A4: B2B BUYER SIDE · SEGMENT A: AUDIENCE AND CONCEPT RESEARCH
A5: Largest entertainment research vendor, revenue ($/yr) | B5: =Assumptions!$B$5 -> 94000000 | C5: =Assumptions!$C$5 -> 94000000 | D5: =Assumptions!$D$5 -> 94000000
A6: Share of that revenue that is film and TV (%) | B6: =Assumptions!$B$6 -> 0.5 | C6: =Assumptions!$C$6 -> 0.65 | D6: =Assumptions!$D$6 -> 1
A7: Second vendor, revenue ($/yr) | B7: =Assumptions!$B$7 -> 43700000 | C7: =Assumptions!$C$7 -> 43700000 | D7: =Assumptions!$D$7 -> 43700000
A8: Share of that revenue that is film and TV (%) | B8: =Assumptions!$B$8 -> 0.8 | C8: =Assumptions!$C$8 -> 0.9 | D8: =Assumptions!$D$8 -> 1
A9: Multiplier for all other vendors (x) | B9: =Assumptions!$B$9 -> 1 | C9: =Assumptions!$C$9 -> 1.5 | D9: =Assumptions!$D$9 -> 2
A10: A. Entertainment audience research spend | B10: =(B5*B6+B7*B8)*B9 -> 81960000 | C10: =(C5*C6+C7*C8)*C9 -> 150645000 | D10: =(D5*D6+D7*D8)*D9 -> 275400000 | E10: Vendor-revenue build: two known vendors x film/TV share, grossed up for the rest of the field. Test screenings sit INSIDE this line.
A12: MEMO North American wide releases (count/yr) | B12: =Assumptions!$B$10 -> 95 | C12: =Assumptions!$C$10 -> 105 | D12: =Assumptions!$D$10 -> 115
A13: MEMO Share of wide releases test-screened (%) | B13: =Assumptions!$B$11 -> 0.75 | C13: =Assumptions!$C$11 -> 0.85 | D13: =Assumptions!$D$11 -> 0.9
A14: MEMO Screenings per tested wide title (count) | B14: =Assumptions!$B$12 -> 2 | C14: =Assumptions!$C$12 -> 3 | D14: =Assumptions!$D$12 -> 4
A15: MEMO Cost per recruited studio screening ($) | B15: =Assumptions!$B$13 -> 10000 | C15: =Assumptions!$C$13 -> 15000 | D15: =Assumptions!$D$13 -> 25000
A16: MEMO Other screenings: limited, streamer films, series (US, $/yr) | B16: =Assumptions!$B$14 -> 1710000 | C16: =Assumptions!$C$14 -> 9200000 | D16: =Assumptions!$D$14 -> 33000000
A17: MEMO Rest-of-world uplift on screenings (x) | B17: =Assumptions!$B$15 -> 1.15 | C17: =Assumptions!$C$15 -> 1.3 | D17: =Assumptions!$D$15 -> 1.5
A18: MEMO A1. Recruited test screenings, global (inside A) | B18: =(B12*B13*B14*B15+B16)*B17 -> 3605250 | C18: =(C12*C13*C14*C15+C16)*C17 -> 17181125 | D18: =(D12*D13*D14*D15+D16)*D17 -> 65025000 | E18: Not summed. Wide releases x share tested x screenings x cost, plus other screenings, x rest-of-world uplift.
A20: MEMO Pre-greenlight share of non-screening research (%) | B20: =Assumptions!$B$16 -> 0.05 | C20: =Assumptions!$C$16 -> 0.1 | D20: =Assumptions!$D$16 -> 0.15
A21: MEMO A3. Pre-greenlight audience research (asked before a film exists) | B21: =B20*(B10-B18) -> 3917737.5 | C21: =C20*(C10-C18) -> 13346388 | D21: =D20*(D10-D18) -> 31556250 | E21: Not summed. The only audience research bought before the money is committed.
A23: MEMO A2. Directly substitutable slice: screenings + pre-greenlight research | B23: =B18+B21 -> 7522987.5 | C23: =C18+C21 -> 30527512 | D23: =D18+D21 -> 96581250 | E23: Not summed. The part of today's research spend a Demand Certificate can replace or precede. Screenings test finished films; only A3 is spent before a film exists.
A25: B2B BUYER SIDE · SEGMENT B: DEMAND ANALYTICS AND DATA SUBSCRIPTIONS
A26: Tier 1 buyers: majors, global streamers, large broadcaster groups (count) | B26: =Assumptions!$B$18 -> 25 | C26: =Assumptions!$C$18 -> 40 | D26: =Assumptions!$D$18 -> 60
A27: Tier 1 content-analytics spend per buyer ($/yr) | B27: =Assumptions!$B$19 -> 1000000 | C27: =Assumptions!$C$19 -> 2500000 | D27: =Assumptions!$D$19 -> 5000000
A28: B1. Tier 1 buyers | B28: =B26*B27 -> 25000000 | C28: =C26*C27 -> 100000000 | D28: =D26*D27 -> 300000000 | E28: Count x spend. Excludes ratings currency.
A30: Tier 2 buyers: mini-majors, regional streamers, scripted commissioners, top distributors (count) | B30: =Assumptions!$B$20 -> 150 | C30: =Assumptions!$C$20 -> 300 | D30: =Assumptions!$D$20 -> 500
A31: Tier 2 annual contract value ($/yr) | B31: =Assumptions!$B$21 -> 100000 | C31: =Assumptions!$C$21 -> 200000 | D31: =Assumptions!$D$21 -> 350000
A32: B2. Tier 2 buyers | B32: =B30*B31 -> 15000000 | C32: =C30*C31 -> 60000000 | D32: =D30*D31 -> 175000000 | E32: Count x contract value.
A34: Tier 3 buyers: independents, sales agents, financiers (count) | B34: =Assumptions!$B$22 -> 1000 | C34: =Assumptions!$C$22 -> 2000 | D34: =Assumptions!$D$22 -> 4000
A35: Tier 3 annual tool spend ($/yr) | B35: =Assumptions!$B$23 -> 3000 | C35: =Assumptions!$C$23 -> 8000 | D35: =Assumptions!$D$23 -> 15000
A36: B3. Tier 3 buyers | B36: =B34*B35 -> 3000000 | C36: =C34*C35 -> 16000000 | D36: =D34*D35 -> 60000000 | E36: Count x tool spend.
A38: B. DEMAND ANALYTICS SUBTOTAL | B38: =B28+B32+B36 -> 43000000 | C38: =C28+C32+C36 -> 176000000 | D38: =D28+D32+D36 -> 535000000 | E38: Cross-check: known vendor revenues sum to roughly $150-250M, which brackets the Base.
A40: B2B BUYER SIDE · SEGMENT C: SCRIPT EVALUATION
A41: US companies with a real development function (count) | B41: =Assumptions!$B$25 -> 800 | C41: =Assumptions!$C$25 -> 1500 | D41: =Assumptions!$D$25 -> 3000
A42: Coverage and evaluation spend per company ($/yr) | B42: =Assumptions!$B$26 -> 10000 | C42: =Assumptions!$C$26 -> 25000 | D42: =Assumptions!$D$26 -> 50000
A43: C1. Production companies: coverage and evaluation | B43: =B41*B42 -> 8000000 | C43: =C41*C42 -> 37500000 | D43: =D41*D42 -> 150000000 | E43: Evaluation spend only. Writer fees and options are excluded (they are the thing being decided, not the cost of deciding).
A45: C. SCRIPT EVALUATION SUBTOTAL | B45: =B43 -> 8000000 | C45: =C43 -> 37500000 | D45: =D43 -> 150000000
A47: MEMO Major and streamer story departments (count) | B47: =Assumptions!$B$27 -> 40 | C47: =Assumptions!$C$27 -> 40 | D47: =Assumptions!$D$27 -> 40
A48: MEMO Story department cost ($/yr) | B48: =Assumptions!$B$28 -> 500000 | C48: =Assumptions!$C$28 -> 1000000 | D48: =Assumptions!$D$28 -> 2000000
A49: MEMO C2. Major and streamer story departments (internal, not in TAM) | B49: =B47*B48 -> 20000000 | C49: =C47*C48 -> 40000000 | D49: =D47*D48 -> 80000000 | E49: Not summed. Internal salaries are not purchasable spend.
A51: B2B BUYER SIDE · MEMO D: SCRIPT ACQUISITION FEE POOL
A52: Studio-level spec sales (count/yr) | B52: =Assumptions!$B$30 -> 40 | C52: =Assumptions!$C$30 -> 70 | D52: =Assumptions!$D$30 -> 120
...

Sheet SAM & SOM
A1: SAM (V1 wedge: English-language, US + UK, horror and genre first) and SOM (year 5), Low / Base / High
A3: Line | B3: Low | C3: Base | D3: High | E3: Build logic
A4: SAM-NOW, B2B: current spend inside the wedge
A5: Substitutable research slice, US + UK genre | B5: ='TAM Build'!B23*Assumptions!$B$75*Assumptions!$B$76 -> 959180.91 | C5: ='TAM Build'!C23*Assumptions!$C$75*Assumptions!$C$76 -> 5189677.1 | D5: ='TAM Build'!D23*Assumptions!$D$75*Assumptions!$D$76 -> 20523516 | E5: TAM Build memo A2 x US+UK share x genre share
A6: Wedge organisations: data tools | B6: =Assumptions!$B$77*Assumptions!$B$78 -> 1208000 | C6: =Assumptions!$C$77*Assumptions!$C$78 -> 6675000 | D6: =Assumptions!$D$77*Assumptions!$D$78 -> 24720000 | E6: Reachable organisations x data-tool spend
A7: Wedge organisations: script evaluation | B7: =Assumptions!$B$77*Assumptions!$B$79 -> 1510000 | C7: =Assumptions!$C$77*Assumptions!$C$79 -> 6675000 | D7: =Assumptions!$D$77*Assumptions!$D$79 -> 20600000 | E7: Reachable organisations x evaluation spend
A8: Genre writers with a finished feature | B8: =Assumptions!$B$80*Assumptions!$B$81*Assumptions!$B$82*Assumptions!$B$83 -> 937500 | C8: =Assumptions!$C$80*Assumptions!$C$81*Assumptions!$C$82*Assumptions!$C$83 -> 4593600 | D8: =Assumptions!$D$80*Assumptions!$D$81*Assumptions!$D$82*Assumptions!$D$83 -> 15210000 | E8: Paying writers x finished feature x horror/thriller x spend per writer
A9: Genre projects packaged by small companies | B9: =Assumptions!$B$84*Assumptions!$B$57 -> 600000 | C9: =Assumptions!$C$84*Assumptions!$C$57 -> 5400000 | D9: =Assumptions!$D$84*Assumptions!$D$57 -> 30000000 | E9: Projects x packaging spend per project
A10: SAM-NOW, B2B | B10: =B5+B6+B7+B8+B9 -> 5214680.9 | C10: =C5+C6+C7+C8+C9 -> 28533277 | D10: =D5+D6+D7+D8+D9 -> 1.1105352e+08 | E10: LAYER DEFINITION: what wedge buyers and creators spend on the problem today.
A12: SAM-NOW, B2C: current spend inside the wedge
A13: SAM fans (count) | B13: =Assumptions!$B$86*Assumptions!$B$85*Assumptions!$B$87 -> 16456000 | C13: =Assumptions!$C$86*Assumptions!$C$85*Assumptions!$C$87 -> 26775000 | D13: =Assumptions!$D$86*Assumptions!$D$85*Assumptions!$D$87 -> 39100000 | E13: US+UK 18-34s x horror affinity x reachable on short-form social. Low end cross-checks to ~18M unique US horror cinema-goers aged 18-34.
A14: SAM-NOW, B2C | B14: =B13*Assumptions!$B$88*Assumptions!$B$89 -> 4114000 | C14: =C13*Assumptions!$C$88*Assumptions!$C$89 -> 26775000 | D14: =D13*Assumptions!$D$88*Assumptions!$D$89 -> 108698000 | E14: SAM fans x share who pay to take part x spend per payer. LAYER DEFINITION: what wedge fans would plausibly already pay; addressable only with pledges or membership.
A16: SAM-NOW, TWO POOLS TOGETHER | B16: =B10+B14 -> 9328680.9 | C16: =C10+C14 -> 55308277 | D16: =D10+D14 -> 2.1975152e+08 | E16: Quote separately.
A17: SAM-now as a share of TAM (%) | B17: =B16/'TAM Build'!B128 -> 0.023653142 | C17: =C16/'TAM Build'!C128 -> 0.061740736 | D17: =D16/'TAM Build'!D128 -> 0.12303221 | E17: Sanity check: a one-genre, two-country wedge should be a single-digit to low-teens share.
A19: REACHABLE REVENUE: wedge organisations at planned list prices
A20: Certificates: organisations x concepts x price | B20: =Assumptions!$B$77*Assumptions!$B$91*Assumptions!$B$92 -> 906000 | C20: =Assumptions!$C$77*Assumptions!$C$91*Assumptions!$C$92 -> 4272000 | D20: =Assumptions!$D$77*Assumptions!$D$91*Assumptions!$D$92 -> 16480000
A21: Market-access seats: one per organisation | B21: =Assumptions!$B$77*Assumptions!$B$93 -> 7248000 | C21: =Assumptions!$C$77*Assumptions!$C$93 -> 12816000 | D21: =Assumptions!$D$77*Assumptions!$D$93 -> 19776000
A22: REACHABLE REVENUE (B2B wedge) | B22: =B20+B21 -> 8154000 | C22: =C20+C21 -> 17088000 | D22: =D20+D21 -> 36256000 | E22: LAYER DEFINITION: every reachable organisation buying at list price.
A23: Check: reachable revenue / buyer-side SAM-now (S1+S2+S3) | B23: =B22/(B5+B6+B7) -> 2.2174596 | C23: =C22/(C5+C6+C7) -> 0.9216989 | D23: =D22/(D5+D6+D7) -> 0.55063888 | E23: At ~100% the plan needs most of what these buyers spend today, or it must grow the category. It is an expansion bet: say so. The $48K seat is ~2x the wedge data-tool budget.
A25: SOM: YEAR-5 REVENUE PLAN
A26: SOM, top-down: B2B SAM-now x capture rate | B26: =B10*Assumptions!$B$95 -> 156440.43 | C26: =C10*Assumptions!$C$95 -> 1711996.6 | D26: =D10*Assumptions!$D$95 -> 11105352 | E26: Capture applies to the wedge product only.
A28: Bottom-up: certificates | B28: =Assumptions!$B$96*Assumptions!$B$92 -> 360000 | C28: =Assumptions!$C$96*Assumptions!$C$92 -> 1600000 | D28: =Assumptions!$D$96*Assumptions!$D$92 -> 6000000
A29: Bottom-up: market-access seats | B29: =Assumptions!$B$97*Assumptions!$B$93 -> 720000 | C29: =Assumptions!$C$97*Assumptions!$C$93 -> 1920000 | D29: =Assumptions!$D$97*Assumptions!$D$93 -> 4320000
A30: Bottom-up: enterprise data feeds | B30: =Assumptions!$B$98*Assumptions!$B$99 -> 90000 | C30: =Assumptions!$C$98*Assumptions!$C$99 -> 360000 | D30: =Assumptions!$D$98*Assumptions!$D$99 -> 1200000
A31: Bottom-up: creator sell-kits | B31: =Assumptions!$B$100*Assumptions!$B$101 -> 60000 | C31: =Assumptions!$C$100*Assumptions!$C$101 -> 400000 | D31: =Assumptions!$D$100*Assumptions!$D$101 -> 2000000
A32: Bottom-up: success fees | B32: =Assumptions!$B$102*Assumptions!$B$103 -> 2000 | C32: =Assumptions!$C$102*Assumptions!$C$103 -> 15000 | D32: =Assumptions!$D$102*Assumptions!$D$103 -> 90000
A33: Monthly active fans (count) | B33: =B13*Assumptions!$B$104*Assumptions!$B$105 -> 24684 | C33: =C13*Assumptions!$C$104*Assumptions!$C$105 -> 200812.5 | D33: =D13*Assumptions!$D$104*Assumptions!$D$105 -> 1094800 | E33: SAM fans x registered x active
A34: Bottom-up: B2C under the current stance | B34: =B33*Assumptions!$B$106 -> 1727.88 | C34: =C33*Assumptions!$C$106 -> 120487.5 | D34: =D33*Assumptions!$D$106 -> 3755164 | E34: Pledge fee + owned-audience value only. B2C is the signal engine, not the revenue line.
A35: SOM, bottom-up: year-5 revenue build | B35: =B28+B29+B30+B31+B32+B34 -> 1233727.9 | C35: =C28+C29+C30+C31+C32+C34 -> 4415487.5 | D35: =D28+D29+D30+D31+D32+D34 -> 17365164
A36: MEMO B2C if membership + sponsorship were adopted (not in SOM) | B36: =B33*Assumptions!$B$107 -> 21228.24 | C36: =C33*Assumptions!$C$107 -> 963900 | D36: =D33*Assumptions!$D$107 -> 17254048 | E36: OPTION NOT DECIDED. Rejected today because it degrades the signal the B2B product sells.
A37: Implied capture of B2B SAM-now (bottom-up B2B lines / SAM-now B2B) | B37: =(B28+B29+B30+B31+B32)/B10 -> 0.23625607 | C37: =(C28+C29+C30+C31+C32)/C10 -> 0.150526 | D37: =(D28+D29+D30+D31+D32)/D10 -> 0.12255353 | E37: Reconciliation: bottom-up implies a capture above the top-down band. The difference is category expansion and must be earned in pilots.
A39: SOM reconciliation midpoint | B39: =(B26+B35)/2 -> 695084.15 | C39: =(C26+C35)/2 -> 3063742.1 | D39: =(D26+D35)/2 -> 14235258 | E39: Average of the two independent builds
A40: Check: SOM midpoint / reachable revenue | B40: =B39/B22 -> 0.085244561 | C40: =C39/C22 -> 0.17929202 | D40: =D39/D22 -> 0.39263178 | E40: Should sit well inside 100%.

Sheet Enumeration
A1: SAM-Now Enumeration: the named-buyer list behind the V1 wedge
A2: Goal: convert B2B SAM-NOW from arithmetic into named organisations with estimated spend. Seed sources: AFM exhibitor list, Cinando, Cannes Marche genre programme (Fantastic Pavilion), Fantasia / Frontieres market, FrightFest, Blood List. Replace the EXAMPLE row.
A4: Organisations listed | B4: =COUNTA(A9:A308) -> 1
A5: Total estimated decision-support spend | B5: =SUM(D9:D308) -> 50000
A6: Coverage of buyer-side SAM-NOW (base case) | B6: =SUM(D9:D308)/('SAM & SOM'!C5+'SAM & SOM'!C6+'SAM & SOM'!C7) -> 0.0026969186 | C6: Counts include the EXAMPLE row until it is replaced.
A8: Organisation | B8: Type | C8: Evidence of genre activity | D8: Est. annual spend ($) | E8: Priority | F8: Owner | G8: Status
A9: EXAMPLE: Example Genre Pictures LLC | B9: Production company | C9: Three horror features released 2023-25; AFM 2025 exhibitor | D9: 50000 | E9: H | F9: Shiv | G9: Not started

Sheet Market Map
A1: Revenue potential estimate by media market: the pools are ALLOCATED, not re-sized
A2: Totals are taken as given and only allocated. World: B2B = 75% estimated content-spend share + 25% share of feature films produced (WIPO/Omdia 2024); B2C = 2025 box office by territory (Gower Street + national bodies) scaled by an estimated fan-spend propensity. Wedge: US/UK split by 18-34 population (B2C) and film-count/content-spend blend (B2B); within the US, B2C = share of TV households (2024-25 universe estimates) x a Hispanic-driven horror index, B2B = judgemental hub shares anchored on WGA membership and buyer HQs; within the UK, B2C = cinema admissions by ITV region (CAA 2024), B2B = London-centric estimate anchored on BFI spend concentration. Shares are blue inputs; every dollar figure is share x the pool on TAM Build / SAM & SOM. Allocation keys are mostly ESTIMATES: see notes. Media markets are plotted as points; no licensed boundary file or licensed measurement data is used.
A4: WORLD: B2B TAM and B2C pool by territory
A5: Market | B5: B2B share | C5: B2C share | D5: B2B $ Low | E5: B2B $ Base | F5: B2B $ High | G5: B2C $ Low | H5: B2C $ Base | I5: B2C $ High | J5: Basis / note
A6: United States + Canada | B6: 0.3615 | C6: 0.4509 | D6: =$B6*'TAM Build'!B$96 -> 56504258 | E6: =$B6*'TAM Build'!C$96 -> 1.6179836e+08 | F6: =$B6*'TAM Build'!D$96 -> 457290270 | G6: =$C6*'TAM Build'!B$112 -> 107354781 | H6: =$C6*'TAM Build'!C$112 -> 202111416 | I6: =$C6*'TAM Build'!D$112 -> 234986535 | J6: Box office 2025: $8,870M (SOURCED). Films: US 544 (WIPO/Omdia 2024) + Canada ~90 ESTIMATE. Dot placed at Los Angeles (media capital).
A7: China | B7: 0.0834 | C7: 0.0752 | D7: =$B7*'TAM Build'!B$96 -> 13035837 | E7: =$B7*'TAM Build'!C$96 -> 37327755 | F7: =$B7*'TAM Build'!D$96 -> 105499332 | G7: =$C7*'TAM Build'!B$112 -> 17904368 | H7: =$C7*'TAM Build'!C$112 -> 33707648 | I7: =$C7*'TAM Build'!D$112 -> 39190480 | J7: Box office 2025: $7,400M (SOURCED). B2C heavily discounted: the fan-spend instruments in the B2C pool (guild votes, Kickstarter-style crowdfunding, Letterboxd-type tiers) are largely inaccessible in China.
A8: Japan | B8: 0.0553 | C8: 0.0425 | D8: =$B8*'TAM Build'!B$96 -> 8643666.5 | E8: =$B8*'TAM Build'!C$96 -> 24750898 | F8: =$B8*'TAM Build'!D$96 -> 69953394 | G8: =$C8*'TAM Build'!B$112 -> 10118825 | H8: =$C8*'TAM Build'!C$112 -> 19050200 | I8: =$C8*'TAM Build'!D$112 -> 22148875 | J8: Box office 2025: $1,790M (SOURCED).
A9: India | B9: 0.0864 | C9: 0.0209 | D9: =$B9*'TAM Build'!B$96 -> 13504752 | E9: =$B9*'TAM Build'!C$96 -> 38670480 | F9: =$B9*'TAM Build'!D$96 -> 109294272 | G9: =$C9*'TAM Build'!B$112 -> 4976081 | H9: =$C9*'TAM Build'!C$112 -> 9368216 | I9: =$C9*'TAM Build'!D$112 -> 10892035 | J9: Box office 2025: $1,540M (DERIVED). Largest film count on earth (2,605) lifts B2B share well above its content-spend share; dot at Mumbai.
A10: United Kingdom + Ireland | B10: 0.05 | C10: 0.0669 | D10: =$B10*'TAM Build'!B$96 -> 7815250 | E10: =$B10*'TAM Build'!C$96 -> 22378750 | F10: =$B10*'TAM Build'!D$96 -> 63249000 | G10: =$C10*'TAM Build'!B$112 -> 15928221 | H10: =$C10*'TAM Build'!C$112 -> 29987256 | I10: =$C10*'TAM Build'!D$112 -> 34864935 | J10: Box office 2025: $1,316M (DERIVED). Films: BFI 193 features into production 2025. 85% of UK film+HETV spend is inward investment (mostly US-commissioned).
A11: France | B11: 0.0322 | C11: 0.0444 | D11: =$B11*'TAM Build'!B$96 -> 5033021 | E11: =$B11*'TAM Build'!C$96 -> 14411915 | F11: =$B11*'TAM Build'!D$96 -> 40732356 | G11: =$C11*'TAM Build'!B$112 -> 10571196 | H11: =$C11*'TAM Build'!C$112 -> 19901856 | I11: =$C11*'TAM Build'!D$112 -> 23139060 | J11: Box office 2025: $1,310M (DERIVED).
A12: Germany | B12: 0.0365 | C12: 0.0354 | D12: =$B12*'TAM Build'!B$96 -> 5705132.5 | E12: =$B12*'TAM Build'!C$96 -> 16336488 | F12: =$B12*'TAM Build'!D$96 -> 46171770 | G12: =$C12*'TAM Build'!B$112 -> 8428386 | H12: =$C12*'TAM Build'!C$112 -> 15867696 | I12: =$C12*'TAM Build'!D$112 -> 18448710 | J12: Box office 2025: $1,044M (DERIVED). Film count ESTIMATE (~250; not in WIPO top list retrieved).
A13: Mexico | B13: 0.0152 | C13: 0.0153 | D13: =$B13*'TAM Build'!B$96 -> 2375836 | E13: =$B13*'TAM Build'!C$96 -> 6803140 | F13: =$B13*'TAM Build'!D$96 -> 19227696 | G13: =$C13*'TAM Build'!B$112 -> 3642777 | H13: =$C13*'TAM Build'!C$112 -> 6858072 | I13: =$C13*'TAM Build'!D$112 -> 7973595 | J13: Box office 2025: $750M (DERIVED).
A14: South Korea | B14: 0.0239 | C14: 0.02 | D14: =$B14*'TAM Build'!B$96 -> 3735689.5 | E14: =$B14*'TAM Build'!C$96 -> 10697042 | F14: =$B14*'TAM Build'!D$96 -> 30233022 | G14: =$C14*'TAM Build'!B$112 -> 4761800 | H14: =$C14*'TAM Build'!C$112 -> 8964800 | I14: =$C14*'TAM Build'!D$112 -> 10423000 | J14: Box office 2025: $737M (DERIVED). Film count ESTIMATE (~200 commercially released local features).
A15: Australia | B15: 0.0128 | C15: 0.0308 | D15: =$B15*'TAM Build'!B$96 -> 2000704 | E15: =$B15*'TAM Build'!C$96 -> 5728960 | F15: =$B15*'TAM Build'!D$96 -> 16191744 | G15: =$C15*'TAM Build'!B$112 -> 7333172 | H15: =$C15*'TAM Build'!C$112 -> 13805792 | I15: =$C15*'TAM Build'!D$112 -> 16051420 | J15: Box office 2025: $650M (ESTIMATE).
A16: Italy | B16: 0.0256 | C16: 0.019 | D16: =$B16*'TAM Build'!B$96 -> 4001408 | E16: =$B16*'TAM Build'!C$96 -> 11457920 | F16: =$B16*'TAM Build'!D$96 -> 32383488 | G16: =$C16*'TAM Build'!B$112 -> 4523710 | H16: =$C16*'TAM Build'!C$112 -> 8516560 | I16: =$C16*'TAM Build'!D$112 -> 9901850 | J16: Box office 2025: $561M (DERIVED).
A17: Spain | B17: 0.0213 | C17: 0.0174 | D17: =$B17*'TAM Build'!B$96 -> 3329296.5 | E17: =$B17*'TAM Build'!C$96 -> 9533347.5 | F17: =$B17*'TAM Build'!D$96 -> 26944074 | G17: =$C17*'TAM Build'!B$112 -> 4142766 | H17: =$C17*'TAM Build'!C$112 -> 7799376 | I17: =$C17*'TAM Build'!D$112 -> 9068010 | J17: Box office 2025: $512M (DERIVED). Film count ESTIMATE (~300).
... A21: Rest of world | B21: 0.1684 | C21: 0.1444 | D21: =$B21*'TAM Build'!B$96 -> 26321762 | E21: =$B21*'TAM Build'!C$96 -> 75371630 | F21: =$B21*'TAM Build'!D$96 -> 213022632 | G21: =$C21*'TAM Build'!B$112 -> 34380196 | H21: =$C21*'TAM Build'!C$112 -> 64725856 | I21: =$C21*'TAM Build'!D$112 -> 75254060 | J21: Box office 2025: $6,091M (DERIVED). Legend line only. Includes Russia/CIS, Netherlands, Turkiye (223 films), Argentina (235 films), Iran, Nigeria, Taiwan, Middle East ex-KSA etc.
A22: Check: shares sum to 100% | B22: =SUM(B6:B21) -> 1 | C22: =SUM(C6:C21) -> 1 | D22: =SUM(D6:D21) -> 156305000 | E22: =SUM(E6:E21) -> 447575000 | F22: =SUM(F6:F21) -> 1264980000 | G22: =SUM(G6:G21) -> 238090000 | H22: =SUM(H6:H21) -> 448240000 | I22: =SUM(I6:I21) -> 521150000
A24: FIRST WEDGE: SAM-now by US media market and UK region
A25: Market | B25: B2B share | C25: B2C share | D25: B2B $ Low | E25: B2B $ Base | F25: B2B $ High | G25: B2C $ Low | H25: B2C $ Base | I25: B2C $ High | J25: Basis / note
A26: New York | B26: 0.1311 | C26: 0.052 | D26: =$B26*'SAM & SOM'!B$10 -> 683644.67 | E26: =$B26*'SAM & SOM'!C$10 -> 3740712.6 | F26: =$B26*'SAM & SOM'!D$10 -> 14559116 | G26: =$C26*'SAM & SOM'!B$14 -> 213928 | H26: =$C26*'SAM & SOM'!C$14 -> 1392300 | I26: =$C26*'SAM & SOM'!D$14 -> 5652296 | J26: Household-share population proxy x horror index 1.0 (estimate). Second buyer/writer hub: WGA East 7,398 members, indie financiers, A24/Neon-type distributors, publishing IP. WGAE count includes news/digital members, so discounted vs raw 35% guild split.
A27: Los Angeles | B27: 0.4259 | C27: 0.0457 | D27: =$B27*'SAM & SOM'!B$10 -> 2220932.6 | E27: =$B27*'SAM & SOM'!C$10 -> 12152323 | F27: =$B27*'SAM & SOM'!D$10 -> 47297692 | G27: =$C27*'SAM & SOM'!B$14 -> 188009.8 | H27: =$C27*'SAM & SOM'!C$14 -> 1223617.5 | I27: =$C27*'SAM & SOM'!D$14 -> 4967498.6 | J27: Household-share population proxy x horror index 1.2 (estimate). Buyer capital: studios, streamers' film groups, agencies, AFM, WGA West 13,713 members. ~45% Hispanic smaller markets> top horror index among the big-3.
A28: Chicago | B28: 0.0164 | C28: 0.025 | D28: =$B28*'SAM & SOM'!B$10 -> 85520.767 | E28: =$B28*'SAM & SOM'!C$10 -> 467945.74 | F28: =$B28*'SAM & SOM'!D$10 -> 1821277.7 | G28: =$C28*'SAM & SOM'!B$14 -> 102850 | H28: =$C28*'SAM & SOM'!C$14 -> 669375 | I28: =$C28*'SAM & SOM'!D$14 -> 2717450 | J28: Household-share population proxy x horror index 1.0 (estimate).
A29: Dallas-Ft. Worth | B29: 0.0123 | C29: 0.0232 | D29: =$B29*'SAM & SOM'!B$10 -> 64140.575 | E29: =$B29*'SAM & SOM'!C$10 -> 350959.31 | F29: =$B29*'SAM & SOM'!D$10 -> 1365958.2 | G29: =$C29*'SAM & SOM'!B$14 -> 95444.8 | H29: =$C29*'SAM & SOM'!C$14 -> 621180 | I29: =$C29*'SAM & SOM'!D$14 -> 2521793.6 | J29: Household-share population proxy x horror index 1.1 (estimate).
A30: Philadelphia | B30: 0.0082 | C30: 0.0197 | D30: =$B30*'SAM & SOM'!B$10 -> 42760.383 | E30: =$B30*'SAM & SOM'!C$10 -> 233972.87 | F30: =$B30*'SAM & SOM'!D$10 -> 910638.83 | G30: =$C30*'SAM & SOM'!B$14 -> 81045.8 | H30: =$C30*'SAM & SOM'!C$14 -> 527467.5 | I30: =$C30*'SAM & SOM'!D$14 -> 2141350.6 | J30: Household-share population proxy x horror index 0.9 (estimate).
A31: Houston | B31: 0.0057 | C31: 0.021 | D31: =$B31*'SAM & SOM'!B$10 -> 29723.681 | E31: =$B31*'SAM & SOM'!C$10 -> 162639.68 | F31: =$B31*'SAM & SOM'!D$10 -> 633005.04 | G31: =$C31*'SAM & SOM'!B$14 -> 86394 | H31: =$C31*'SAM & SOM'!C$14 -> 562275 | I31: =$C31*'SAM & SOM'!D$14 -> 2282658 | J31: Household-share population proxy x horror index 1.1 (estimate).
A32: Atlanta | B32: 0.0287 | C32: 0.0175 | D32: =$B32*'SAM & SOM'!B$10 -> 149661.34 | E32: =$B32*'SAM & SOM'!C$10 -> 818905.05 | F32: =$B32*'SAM & SOM'!D$10 -> 3187235.9 | G32: =$C32*'SAM & SOM'!B$14 -> 71995 | H32: =$C32*'SAM & SOM'!C$14 -> 468562.5 | I32: =$C32*'SAM & SOM'!D$14 -> 1902215 | J32: Household-share population proxy x horror index 0.9 (estimate). Production hub (Georgia tax credit, Tyler Perry Studios, Trilith); fewer buyers than crew.
A33: Washington, DC | B33: 0.0082 | C33: 0.0173 | D33: =$B33*'SAM & SOM'!B$10 -> 42760.383 | E33: =$B33*'SAM & SOM'!C$10 -> 233972.87 | F33: =$B33*'SAM & SOM'!D$10 -> 910638.83 | G33: =$C33*'SAM & SOM'!B$14 -> 71172.2 | H33: =$C33*'SAM & SOM'!C$14 -> 463207.5 | I33: =$C33*'SAM & SOM'!D$14 -> 1880475.4 | J33: Household-share population proxy x horror index 1.0 (estimate).
A34: Boston | B34: 0.0082 | C34: 0.0164 | D34: =$B34*'SAM & SOM'!B$10 -> 42760.383 | E34: =$B34*'SAM & SOM'!C$10 -> 233972.87 | F34: =$B34*'SAM & SOM'!D$10 -> 910638.83 | G34: =$C34*'SAM & SOM'!B$14 -> 67469.6 | H34: =$C34*'SAM & SOM'!C$14 -> 439110 | I34: =$C34*'SAM & SOM'!D$14 -> 1782647.2 | J34: Household-share population proxy x horror index 0.9 (estimate).
A35: San Francisco-Oakland-San Jose | B35: 0.0246 | C35: 0.0174 | D35: =$B35*'SAM & SOM'!B$10 -> 128281.15 | E35: =$B35*'SAM & SOM'!C$10 -> 701918.62 | F35: =$B35*'SAM & SOM'!D$10 -> 2731916.5 | G35: =$C35*'SAM & SOM'!B$14 -> 71583.6 | H35: =$C35*'SAM & SOM'!C$14 -> 465885 | I35: =$C35*'SAM & SOM'!D$14 -> 1891345.2 | J35: Household-share population proxy x horror index 1.0 (estimate). Streamer/tech HQs (Netflix Los Gatos, Apple, YouTube) lift B2B above population share.
A36: Tampa-St. Petersburg | B36: 0.0025 | C36: 0.015 | D36: =$B36*'SAM & SOM'!B$10 -> 13036.702 | E36: =$B36*'SAM & SOM'!C$10 -> 71333.193 | F36: =$B36*'SAM & SOM'!D$10 -> 277633.79 | G36: =$C36*'SAM & SOM'!B$14 -> 61710 | H36: =$C36*'SAM & SOM'!C$14 -> 401625 | I36: =$C36*'SAM & SOM'!D$14 -> 1630470 | J36: Household-share population proxy x horror index 1.0 (estimate).
A37: Phoenix | B37: 0.0033 | C37: 0.0158 | D37: =$B37*'SAM & SOM'!B$10 -> 17208.447 | E37: =$B37*'SAM & SOM'!C$10 -> 94159.815 | F37: =$B37*'SAM & SOM'!D$10 -> 366476.6 | G37: =$C37*'SAM & SOM'!B$14 -> 65001.2 | H37: =$C37*'SAM & SOM'!C$14 -> 423045 | I37: =$C37*'SAM & SOM'!D$14 -> 1717428.4 | J37: Household-share population proxy x horror index 1.1 (estimate).
... A59: Northern Ireland | B59: 0.0018 | C59: 0.0056 | D59: =$B59*'SAM & SOM'!B$10 -> 9386.4256 | E59: =$B59*'SAM & SOM'!C$10 -> 51359.899 | F59: =$B59*'SAM & SOM'!D$10 -> 199896.33 | G59: =$C59*'SAM & SOM'!B$14 -> 23038.4 | H59: =$C59*'SAM & SOM'!C$14 -> 149940 | I59: =$C59*'SAM & SOM'!D$14 -> 608708.8 | J59: Household-share population proxy x horror index 1.0 (estimate).
A60: Check: shares sum to 100% | B60: =SUM(B26:B59) -> 1 | C60: =SUM(C26:C59) -> 1 | D60: =SUM(D26:D59) -> 5214680.9 | E60: =SUM(E26:E59) -> 28533277 | F60: =SUM(F26:F59) -> 1.1105352e+08 | G60: =SUM(G26:G59) -> 4114000 | H60: =SUM(H26:H59) -> 26775000 | I60: =SUM(I26:I59) -> 108698000
A62: SOURCES
A63: Gower Street Analytics - Highest grossing December since 2019 adds $3.5bn for $33.6bn global total in 2025 (2026) https://gower.st/articles/highest-grossing-december-since-2019-3-5-billion-33-6-billion-global-total-2025/
A64: Variety - 'Demon Slayer' powers Japan's box office to $1.79 billion in 2025 (Eiren) (2026) https://variety.com/2026/film/box-office/demon-slayer-japan-box-office-2025-1236644196/
A65: Ormax Box Office Report 2025 (India gross INR 13,395 cr) (2026) https://www.ormaxmedia.com/stories/the-ormax-box-office-report-2025.html
A66: BFI official statistics 2025: GBP 6.8bn film+HETV spend; 193 films; UK/IE box office GBP 996.8M (2026) https://www.bfi.org.uk/news/official-bfi-statistics-2025
A67: Boxoffice Pro FR - CNC 2025 bilan: 156.2M admissions, avg ticket EUR 7.42 (2026) https://www.boxofficepro.fr/cannes-2026-le-cnc-dresse-la-fiche-didentite-du-cinema-en-2025/
...

Sheet Sensitivity
A1: One-way sensitivity: TAM with a single driver moved Low/High, all else Base
A3: Driver | B3: TAM at driver Low | C3: TAM at driver High | D3: Swing (High - Low) | E3: Swing as % of base TAM
A4: Paying guild members (vote on releases) | B4: ='TAM Build'!C128-'TAM Build'!C101+Assumptions!$B$61*Assumptions!$C$62 -> 715115000 | C4: ='TAM Build'!C128-'TAM Build'!C101+Assumptions!$D$61*Assumptions!$C$62 -> 929175000 | D4: =C4-B4 -> 214060000 | E4: =D4/'TAM Build'!C128 -> 0.23895559
A5: Tier 1 analytics spend per buyer | B5: ='TAM Build'!C128-'TAM Build'!C28+Assumptions!$C$18*Assumptions!$B$19 -> 835815000 | C5: ='TAM Build'!C128-'TAM Build'!C28+Assumptions!$C$18*Assumptions!$D$19 -> 995815000 | D5: =C5-B5 -> 160000000 | E5: =D5/'TAM Build'!C128 -> 0.17860831
A6: Other research vendors multiplier | B6: ='TAM Build'!C128-'TAM Build'!C10+(Assumptions!$C$5*Assumptions!$C$6+Assumptions!$C$7*Assumptions!$C$8)*Assumptions!$B$9 -> 845600000 | C6: ='TAM Build'!C128-'TAM Build'!C10+(Assumptions!$C$5*Assumptions!$C$6+Assumptions!$C$7*Assumptions!$C$8)*Assumptions!$D$9 -> 946030000 | D6: =C6-B6 -> 100430000 | E6: =D6/'TAM Build'!C128 -> 0.1121102
A7: Packaging spend per project | B7: ='TAM Build'!C128-'TAM Build'!C92+Assumptions!$C$56*Assumptions!$B$57+Assumptions!$C$58*Assumptions!$C$59 -> 865815000 | C7: ='TAM Build'!C128-'TAM Build'!C92+Assumptions!$C$56*Assumptions!$D$57+Assumptions!$C$58*Assumptions!$C$59 -> 955815000 | D7: =C7-B7 -> 90000000 | E7: =D7/'TAM Build'!C128 -> 0.10046717
A8: Tier 1 buyer count | B8: ='TAM Build'!C128-'TAM Build'!C28+Assumptions!$B$18*Assumptions!$C$19 -> 858315000 | C8: ='TAM Build'!C128-'TAM Build'!C28+Assumptions!$D$18*Assumptions!$C$19 -> 945815000 | D8: =C8-B8 -> 87500000 | E8: =D8/'TAM Build'!C128 -> 0.097676418
A9: Tier 2 contract value | B9: ='TAM Build'!C128-'TAM Build'!C32+Assumptions!$C$20*Assumptions!$B$21 -> 865815000 | C9: ='TAM Build'!C128-'TAM Build'!C32+Assumptions!$C$20*Assumptions!$D$21 -> 940815000 | D9: =C9-B9 -> 75000000 | E9: =D9/'TAM Build'!C128 -> 0.083722644
A10: Film/TV share of largest vendor revenue | B10: ='TAM Build'!C128-'TAM Build'!C10+(Assumptions!$C$5*Assumptions!$B$6+Assumptions!$C$7*Assumptions!$C$8)*Assumptions!$C$9 -> 874665000 | C10: ='TAM Build'!C128-'TAM Build'!C10+(Assumptions!$C$5*Assumptions!$D$6+Assumptions!$C$7*Assumptions!$C$8)*Assumptions!$C$9 -> 945165000 | D10: =C10-B10 -> 70500000 | E10: =D10/'TAM Build'!C128 -> 0.078699285
A11: Tier 2 buyer count | B11: ='TAM Build'!C128-'TAM Build'!C32+Assumptions!$B$20*Assumptions!$C$21 -> 865815000 | C11: ='TAM Build'!C128-'TAM Build'!C32+Assumptions!$D$20*Assumptions!$C$21 -> 935815000 | D11: =C11-B11 -> 70000000 | E11: =D11/'TAM Build'!C128 -> 0.078141134
A12: Features actively packaged | B12: ='TAM Build'!C128-'TAM Build'!C92+Assumptions!$B$56*Assumptions!$C$57+Assumptions!$C$58*Assumptions!$C$59 -> 875815000 | C12: ='TAM Build'!C128-'TAM Build'!C92+Assumptions!$D$56*Assumptions!$C$57+Assumptions!$C$58*Assumptions!$C$59 -> 935815000 | D12: =C12-B12 -> 60000000 | E12: =D12/'TAM Build'!C128 -> 0.066978115
A13: Companies with a development function | B13: ='TAM Build'!C128-'TAM Build'!C43+Assumptions!$B$25*Assumptions!$C$26 -> 878315000 | C13: ='TAM Build'!C128-'TAM Build'!C43+Assumptions!$D$25*Assumptions!$C$26 -> 933315000 | D13: =C13-B13 -> 55000000 | E13: =D13/'TAM Build'!C128 -> 0.061396605
A14: Film crowdfunding pledges, largest platform | B14: ='TAM Build'!C128-'TAM Build'!C105+Assumptions!$B$63+Assumptions!$C$64 -> 885815000 | C14: ='TAM Build'!C128-'TAM Build'!C105+Assumptions!$D$63+Assumptions!$C$64 -> 910815000 | D14: =C14-B14 -> 25000000 | E14: =D14/'TAM Build'!C128 -> 0.027907548
A15: Paid contest entries | B15: ='TAM Build'!C128-'TAM Build'!C69+Assumptions!$B$39*Assumptions!$C$40+Assumptions!$B$39*Assumptions!$C$41*Assumptions!$C$42 -> 889815000 | C15: ='TAM Build'!C128-'TAM Build'!C69+Assumptions!$D$39*Assumptions!$C$40+Assumptions!$D$39*Assumptions!$C$41*Assumptions!$C$42 -> 907065000 | D15: =C15-B15 -> 17250000 | E15: =D15/'TAM Build'!C128 -> 0.019256208
A17: One-way sensitivity: SAM-now (two pools) with a single driver moved Low/High, all else Base
A18: Driver | B18: SAM at driver Low | C18: SAM at driver High | D18: Swing (High - Low) | E18: Swing as % of base SAM
A19: Share of SAM fans who pay to take part | B19: ='SAM & SOM'!C16-'SAM & SOM'!C14+Assumptions!$C$86*Assumptions!$C$85*Assumptions!$C$87*Assumptions!$B$88*Assumptions!$C$89 -> 41920777 | C19: ='SAM & SOM'!C16-'SAM & SOM'!C14+Assumptions!$C$86*Assumptions!$C$85*Assumptions!$C$87*Assumptions!$D$88*Assumptions!$C$89 -> 82083277 | D19: =C19-B19 -> 40162500 | E19: =D19/'SAM & SOM'!C16 -> 0.72615713
A20: Spend per paying fan | B20: ='SAM & SOM'!C16-'SAM & SOM'!C14+Assumptions!$C$86*Assumptions!$C$85*Assumptions!$C$87*Assumptions!$C$88*Assumptions!$B$89 -> 41920777 | C20: ='SAM & SOM'!C16-'SAM & SOM'!C14+Assumptions!$C$86*Assumptions!$C$85*Assumptions!$C$87*Assumptions!$C$88*Assumptions!$D$89 -> 65750527 | D20: =C20-B20 -> 23829750 | E20: =D20/'SAM & SOM'!C16 -> 0.43085323
A21: Horror affinity among 18-34s | B21: ='SAM & SOM'!C16-'SAM & SOM'!C14+Assumptions!$C$86*Assumptions!$B$85*Assumptions!$C$87*Assumptions!$C$88*Assumptions!$C$89 -> 45363277 | C21: ='SAM & SOM'!C16-'SAM & SOM'!C14+Assumptions!$C$86*Assumptions!$D$85*Assumptions!$C$87*Assumptions!$C$88*Assumptions!$C$89 -> 66783277 | D21: =C21-B21 -> 21420000 | E21: =D21/'SAM & SOM'!C16 -> 0.3872838
A22: Data-tool spend per wedge organisation | B22: ='SAM & SOM'!C16-'SAM & SOM'!C6+Assumptions!$C$77*Assumptions!$B$78 -> 50769277 | C22: ='SAM & SOM'!C16-'SAM & SOM'!C6+Assumptions!$C$77*Assumptions!$D$78 -> 64653277 | D22: =C22-B22 -> 13884000 | E22: =D22/'SAM & SOM'!C16 -> 0.25102933
A23: Reachable buyer organisations | B23: ='SAM & SOM'!C16-'SAM & SOM'!C6-'SAM & SOM'!C7+Assumptions!$B$77*(Assumptions!$C$78+Assumptions!$C$79) -> 49508277 | C23: ='SAM & SOM'!C16-'SAM & SOM'!C6-'SAM & SOM'!C7+Assumptions!$D$77*(Assumptions!$C$78+Assumptions!$C$79) -> 62558277 | D23: =C23-B23 -> 13050000 | E23: =D23/'SAM & SOM'!C16 -> 0.23595022
A24: Genre projects packaged by small companies | B24: ='SAM & SOM'!C16-'SAM & SOM'!C9+Assumptions!$B$84*Assumptions!$C$57 -> 52308277 | C24: ='SAM & SOM'!C16-'SAM & SOM'!C9+Assumptions!$D$84*Assumptions!$C$57 -> 61908277 | D24: =C24-B24 -> 9600000 | E24: =D24/'SAM & SOM'!C16 -> 0.17357257
A25: Writers: horror or thriller share | B25: ='SAM & SOM'!C16-'SAM & SOM'!C8+Assumptions!$C$80*Assumptions!$C$81*Assumptions!$B$82*Assumptions!$C$83 -> 53846677 | C25: ='SAM & SOM'!C16-'SAM & SOM'!C8+Assumptions!$C$80*Assumptions!$C$81*Assumptions!$D$82*Assumptions!$C$83 -> 56978677 | D25: =C25-B25 -> 3132000 | E25: =D25/'SAM & SOM'!C16 -> 0.056628052
A27: Rows are ranked by swing at the input values this file shipped with. The top rows are where a week of validation moves the answer most.
